<mujoco model="alexander_v1_full_body">
    <compiler angle="radian" eulerseq="XYZ" meshdir="../meshes" autolimits="true"/>

    <option iterations="3" ls_iterations="5" timestep="0.002" integrator="Euler">
        <flag eulerdamp="disable"/>
    </option>

    <default>
        <default class="alexander">
            <joint damping="2" frictionloss="0.3"/>
            <position inheritrange="2"/>
            <default class="alexander/spine">
                <joint axis="0 0 1" range="-0.5235987756 0.5235987756"/>
                <position forcerange="-150 150" kp="112"/>
            </default>
            <default class="alexander/hip">
                <default class="alexander/hip/x">
                    <joint axis="1 0 0" armature="0.004085"/>
                    <position forcerange="-150 150" kp="112"/>
                    <default class="alexander/hip/x/left">
                        <joint range="-0.3490658504 0.872664626"/>
                    </default>
                    <default class="alexander/hip/x/right">
                        <joint range="-0.872664626 0.3490658504"/>
                    </default>
                </default>
                <default class="alexander/hip/y">
                    <joint axis="0 1 0" range="-2.61799 0.785398" armature="0.01026"/>
                    <position forcerange="-200 200" kp="150"/>
                </default>
                <default class="alexander/hip/z">
                    <joint axis="0 0 1" armature="0.00124"/>
                    <position forcerange="-60 60" kp="45"/>
                    <default class="alexander/hip/z/left">
                        <joint range="-0.3490658504 1.0472"/>
                    </default>
                    <default class="alexander/hip/z/right">
                        <joint range="-1.0472 0.3490658504"/>
                    </default>
                </default>
            </default>
            <default class="alexander/knee">
                <joint axis="0 1 0" range="0.0 2.445206282" armature="0.01026"/>
                <position forcerange="-200 200" kp="150"/>
            </default>
            <default class="alexander/ankle">
                <joint armature="0.002301"/>
                <default class="alexander/ankle/x">
                    <joint axis="1 0 0" range="-1.0472 0.523599"/>
                    <position forcerange="-90 90" kp="67"/>
                </default>
                <default class="alexander/ankle/y">
                    <joint axis="0 1 0" range="-0.436332 0.436332"/>
                    <position forcerange="-180 180" kp="135"/>
                </default>
            </default>
            <default class="alexander/shoulder">
                <default class="alexander/shoulder/y">
                    <joint axis="0 1 0" range="-3.141592 1.22173" armature="0.01"/>
                    <position forcerange="-150 150" kp="112.5"/>
                </default>
                <default class="alexander/shoulder/x">
                    <joint axis="1 0 0" armature="0.01"/>
                    <position forcerange="-100 100" kp="75"/>
                    <default class="alexander/shoulder/x/left">
                        <joint range="-0.349066 2.79253"/>
                    </default>
                    <default class="alexander/shoulder/x/right">
                        <joint range="-2.79253 0.349066"/>
                    </default>
                </default>
                <default class="alexander/shoulder/z">
                    <joint axis="0 0 1" armature="0.01"/>
                    <position forcerange="-80 80" kp="60"/>
                    <default class="alexander/shoulder/z/left">
                        <joint range="-1.91986 1.22173"/>
                    </default>
                    <default class="alexander/shoulder/z/right">
                        <joint range="-1.22173 1.91986"/>
                    </default>
                </default>
            </default>
            <default class="alexander/elbow">
                <joint axis="0 1 0" range="-2.35619 0.174532925" armature="0.01"/>
                <position forcerange="-80 80" kp="60"/>
            </default>
            <default class="alexander/wrist">
                <position forcerange="-20 20" kp="15"/>
                <default class="alexander/wrist/z">
                    <joint axis="0 0 1" range="-2.61799 2.61799" armature="0.01"/>
                </default>
                <default class="alexander/wrist/x">
                    <joint axis="1 0 0" armature="0.01"/>
                    <default class="alexander/wrist/x/left">
                        <joint range="-1.8326 0.610865"/>
                    </default>
                    <default class="alexander/wrist/x/right">
                        <joint range="-0.610865 1.8326"/>
                    </default>
                </default>
            </default>
            <default class="alexander/neck">
                <position forcerange="-20 20" kp="15"/>
                <default class="alexander/neck/z">
                    <joint axis="0 0 1" range="-1.5708 1.5708" armature="0.01"/>
                </default>
                <default class="alexander/neck/y">
                    <joint axis="0 1 0" range="-1.0472 1.0472" armature="0.01"/>
                </default>
            </default>
            <default class="alexander/imu">
                <site group="4" rgba="0 0 1 0.4"/>
                <default class="alexander/imu/pelvis">
                    <site pos="-0.08687724 0.01225028 -0.08051472"/>
                </default>
                <default class="alexander/imu/hip">
                    <default class="alexander/imu/hip/left">
                        <site pos="-0.01922309 0.10145013 -0.01488788" euler="-1.570796 0 1.570796"/>
                    </default>
                    <default class="alexander/imu/hip/right">
                        <site pos="-0.01922309 -0.07694987 -0.01488788" euler="-1.570796 0 1.570796"/>
                    </default>
                </default>
                <default class="alexander/imu/thigh">
                    <default class="alexander/imu/thigh/left">
                        <site pos="0.10004 0.03746 -0.21194" euler="1.6947717585 0 1.570796"/>
                    </default>
                    <default class="alexander/imu/thigh/right">
                        <site pos="0.10003618 -0.033541826 -0.21194191" euler="1.6947717585 0 1.570796"/>
                    </default>
                </default>
                <default class="alexander/imu/shin">
                    <default class="alexander/imu/shin/left">
                        <site pos="0.05655120 0.00084826 -0.15664831" euler="1.403695170631842 0 -1.570796"/>
                    </default>
                    <default class="alexander/imu/shin/right">
                        <site pos="0.05673025 -0.00875818 -0.15674961" euler="1.403695170631842 0 -1.570796"/>
                    </default>
                </default>
                <default class="alexander/imu/foot">
                    <site pos="-0.03575526 0.01180178 -0.04979705"/>
                </default>
                <default class="alexander/imu/torso">
                    <site pos="0.04529 -0.02427 0.33757" euler="3.141592 0 0"/>
                </default>
                <default class="alexander/imu/head">
                    <site pos="0.040556 -0.014155 0.057016" euler="0.56723 0.0 1.5708"/>
                </default>
                <default class="alexander/imu/shoulder_y">
                    <default class="alexander/imu/shoulder_y/left">
                        <site pos="0.0174 0.06944 -0.03025" euler="-1.570796 1.570796 0"/>
                    </default>
                    <default class="alexander/imu/shoulder_y/right">
                        <site pos="0.0175 -0.0704 -0.00778" euler="1.570796 -1.570796 0"/>
                    </default>
                </default>
                <default class="alexander/imu/shoulder_z">
                    <default class="alexander/imu/shoulder_z/left">
                        <site pos="-0.00763459 -0.0123324 -0.318" euler="-1.570796 3.1415926 -0.314159"/>
                    </default>
                    <default class="alexander/imu/shoulder_z/right">
                        <site pos="0.002 0.016 -0.318" euler="1.570796 0 0.314159"/>
                    </default>
                </default>
                <default class="alexander/imu/wrist_z">
                    <default class="alexander/imu/wrist_z/left">
                        <site pos="-0.033554 0.010450 -0.148527" euler="1.571 0.0 1.571"/>
                    </default>
                    <default class="alexander/imu/wrist_z/right">
                        <site pos="-0.033554 0.010450 -0.148527" euler="1.571 0.0 1.571"/>
                    </default>
                </default>
                <default class="alexander/imu/gripper_z">
                    <default class="alexander/imu/gripper_z/left">
                        <site pos="0 0 0" euler="0 0 0"/>
                    </default>
                    <default class="alexander/imu/gripper_z/right">
                        <site pos="0 0 0" euler="0 0 0"/>
                    </default>
                </default>
            </default>
            <default class="alexander/visual">
                <geom contype="0" conaffinity="0" type="mesh"/>
            </default>
            <default class="alexander/collision">
                <geom group="3" contype="1" conaffinity="1" rgba="0 1 0 0.4"/>
                <default class="alexander/collision/thigh">
                    <geom type="capsule" euler="0 -0.25 0" size="0.095 0.11" condim="1" friction="0.8"/>
                </default>
                <default class="alexander/collision/foot">
                    <geom type="box" size="0.0985 0.045 0.01" pos="0.045 0.0 -0.0625" solimp="0.9 .95 0.01" condim="3" friction="0.8"/>
                </default>
            </default>
        </default>
    </default>

    <asset>
        <material name="metal" rgba=".9 .95 .95 1"/>
        <material name="black" rgba="0 0 0 1"/>
        <material name="white" rgba="1 1 1 1"/>
        <material name="gray" rgba="0.671705 0.692426 0.774270 1"/>
        <mesh name="left_ankle" file="../../meshes/legs/AnklePitchLink.obj"/>
        <mesh name="left_foot" file="../../meshes/legs/Foot.obj"/>
        <mesh name="left_hip_x" file="../../meshes/legs/LeftHipRollLink.obj"/>
        <mesh name="left_hip_z" file="../../meshes/legs/LeftHipYawLink.obj"/>
        <mesh name="left_shin" file="../../meshes/legs/LeftShin.obj"/>
        <mesh name="left_thigh" file="../../meshes/legs/LeftThigh.obj"/>
        <mesh name="pelvis" file="../../meshes/legs/Pelvis.obj"/>
        <mesh name="right_ankle" file="../../meshes/legs/AnklePitchLink.obj"/>
        <mesh name="right_foot" file="../../meshes/legs/Foot.obj"/>
        <mesh name="right_hip_x" file="../../meshes/legs/RightHipRollLink.obj"/>
        <mesh name="right_hip_z" file="../../meshes/legs/RightHipYawLink.obj"/>
        <mesh name="right_shin" file="../../meshes/legs/RightShin.obj"/>
        <mesh name="right_thigh" file="../../meshes/legs/RightThigh.obj"/>
        <mesh name="head" file="../../meshes/ALX02_01_A02_HeadLink.obj"/>
        <mesh name="torso" file="../../meshes/torso.obj"/>
        <mesh name="left_shoulder_y" file="../../meshes/cycloidal_arm/LeftShoulderPitchLink.obj"/>
        <mesh name="left_shoulder_x" file="../../meshes/cycloidal_arm/LeftShoulderRollLink_shortBicep.obj"/>
        <mesh name="left_shoulder_z" file="../../meshes/cycloidal_arm/LeftShoulderYawLink.obj"/>
        <mesh name="left_elbow_y" file="../../meshes/cycloidal_arm/LeftElbowPitchLink.obj"/>
        <mesh name="left_wrist_z" file="../../meshes/cycloidal_arm/LeftWristYawLink.obj"/>
        <mesh name="left_wrist_x" file="../../meshes/cycloidal_arm/LeftWristRollLink.obj"/>
        <mesh name="left_gripper" file="../../meshes/cycloidal_arm/nub.obj" inertia="convex"/>
        <mesh name="right_shoulder_y" file="../../meshes/cycloidal_arm/RightShoulderPitchLink.obj"/>
        <mesh name="right_shoulder_x" file="../../meshes/cycloidal_arm/RightShoulderRollLink_shortBicep.obj"/>
        <mesh name="right_shoulder_z" file="../../meshes/cycloidal_arm/RightShoulderYawLink.obj"/>
        <mesh name="right_elbow_y" file="../../meshes/cycloidal_arm/RightElbowPitchLink.obj"/>
        <mesh name="right_wrist_z" file="../../meshes/cycloidal_arm/RightWristYawLink.obj"/>
        <mesh name="right_wrist_x" file="../../meshes/cycloidal_arm/RightWristRollLink.obj"/>
        <mesh name="right_gripper" file="../../meshes/cycloidal_arm/nub.obj" inertia="convex"/>
    </asset>

    <worldbody>
         <body name="pelvis_link" pos="0.0 0.0 1.0" childclass="alexander">
            <inertial 
                pos="-0.08354287 0.00005291 -0.03484828"
                mass="9.50083635"
                fullinertia="0.03428688 0.05178848 0.06001929 0.00001151 0.00015935 0.00004514"
            />
            <freejoint/>
            <geom mesh="pelvis" material="gray" class="alexander/visual"/>
            <site name="imu_pelvis" class="alexander/imu/pelvis"/>
            <body name="left_hip_x" pos="-0.162 0.0595 -0.015">
                <inertial 
                    pos="0.04350911	0.08708606 -0.03525761"
                    mass="2.32977961"
                    fullinertia="0.00467452 0.00516613 0.00553124 -0.00058626 0.00013124 0.00048141"
                />
                <joint name="left_hip_x" class="alexander/hip/x/left"/>
                <geom mesh="left_hip_x" material="gray" class="alexander/visual"/>
                <site name="imu_left_hip" class="alexander/imu/hip/left"/>
                <body name="left_hip_z" pos="0.06	0.1	-0.08">
                    <inertial 
                        pos="0.04549595	-0.00525571	-0.00937454"
                        mass="0.77281362"
                        fullinertia="0.00317639 0.00345182 0.00313245 0.00005807 0.00080598 0.00047441"
                    />
                    <joint name="left_hip_z" class="alexander/hip/z/left"/>
                    <geom mesh="left_hip_z" material="gray" class="alexander/visual"/>
                    <body name="left_thigh" pos="0.1045	-0.0573	-0.0525">
                        <inertial 
                            pos="0.01417302 0.03268781 -0.10548314"
                            mass="7.75"
                            fullinertia="0.09264028 0.09733033 0.02803877 0.00038532 0.00916409 -0.0043516"
                        />
                        <joint name="left_hip_y" class="alexander/hip/y"/>
                        <geom mesh="left_thigh" material="gray" class="alexander/visual"/>
                        <geom name="left_thigh_collision" pos="0.015 0.025 -0.125" class="alexander/collision/thigh"/>
                        <site name="imu_left_thigh" class="alexander/imu/thigh/left"/>
                        <body name="left_shin" pos="0 0.018 -0.32">
                            <inertial 
                                pos="0.03807965	-0.00108105	-0.12410027"
                                mass="6.31087157"
                                fullinertia="0.08823148 0.09163264 0.01569601 -0.00054706 -0.00634132 0.00002714"
                            />
                            <joint name="left_knee_y" class="alexander/knee"/>
                            <geom mesh="left_shin" material="gray" class="alexander/visual"/>
                            <site name="imu_left_shin" class="alexander/imu/shin/left"/>
                            <body name="left_ankle" pos="0 0 -0.41">
                                <inertial 
                                    pos="2.94E-07 2.22E-07 -0.00462997"
                                    mass="0.05045632"
                                    fullinertia="0.00001733 0.00000714 0.00001851 2.12E-10 -1.26E-10 -2.02E-11"
                                />
                                <joint name="left_ankle_y" class="alexander/ankle/y"/>
                                <geom mesh="left_ankle" material="gray" class="alexander/visual"/>
                                <body name="left_foot" pos="0 0 -0.012">
                                    <inertial 
                                        pos="0.03793372	-0.00000219	-0.0443663"
                                        mass="1.28288609"
                                        fullinertia="0.00131328 0.00385286 0.00406301 0.00001057 0.00036242 -0.0000069"
                                    />
                                    <joint name="left_ankle_x" class="alexander/ankle/x"/>
                                    <geom mesh="left_foot" material="gray" class="alexander/visual"/>
                                    <geom name="left_foot_collision" class="alexander/collision/foot"/>
                                    <site name="imu_left_foot" class="alexander/imu/foot"/>
                                    <site name="left_foot_site"/>
                                </body>
                            </body>
                        </body>
                    </body>
                </body>
            </body>
            <body name="right_hip_x" pos="-0.162	-0.0595	-0.015">
                <inertial 
                    pos="0.04351957	-0.08688935	-0.03525357"
                    mass="2.32977248"
                    fullinertia="0.00467576 0.00516385 0.00552901 0.00061004 0.00013038 -0.00047381"
                />
                <joint name="right_hip_x" class="alexander/hip/x/right"/>
                <geom mesh="right_hip_x" material="gray" class="alexander/visual"/>
                <site name="imu_right_hip" class="alexander/imu/hip/right"/>
                <body name="right_hip_z" pos="0.06 -0.1 -0.08">
                    <inertial 
                        pos="0.04549274 0.00525784 -0.00937505"
                        mass="0.77281055"
                        fullinertia="0.00317639 0.00345166 0.00313223 -0.00005765 0.00080587 -0.00047466"
                    />
                    <joint name="right_hip_z" class="alexander/hip/z/right"/>
                    <geom mesh="right_hip_z" material="gray" class="alexander/visual"/>
                    <body name="right_thigh" pos="0.1045 0.0573 -0.0525">
                        <inertial 
                            pos="0.01411846 -0.03282392 -0.10542795"
                            mass="7.75"
                            fullinertia="0.09273162 0.09738701 0.02802165 -0.00026689 0.00921343 0.00422485"
                        />
                        <joint name="right_hip_y" class="alexander/hip/y"/>
                        <geom mesh="right_thigh" material="gray" class="alexander/visual"/>
                        <geom name="right_thigh_collision" pos="0.015 -0.025 -0.125" class="alexander/collision/thigh"/>
                        <site name="imu_right_thigh" class="alexander/imu/thigh/right"/>
                        <body name="right_shin" pos="0 -0.018 -0.32">
                            <inertial 
                                pos="0.03807648	0.00113375 -0.12408765"
                                mass="6.31087157"
                                fullinertia="0.08705693 0.090231 0.01554032 0.00057277 -0.00674654 0.00028332"
                            />
                            <joint name="right_knee_y" class="alexander/knee"/>
                            <geom mesh="right_shin" material="gray" class="alexander/visual"/>
                            <site name="imu_right_shin" class="alexander/imu/shin/right"/>
                            <body name="right_ankle" pos="0 0 -0.41">
                                <inertial 
                                    pos="2.94E-07 2.22E-07 -0.00462997"
                                    mass="0.05045632"
                                    fullinertia="0.00001733 0.00000714 0.00001851 2.12E-10 -1.26E-10 -2.02E-11"
                                />
                                <joint name="right_ankle_y" class="alexander/ankle/y"/>
                                <geom mesh="right_ankle" material="gray" class="alexander/visual"/>
                                <body name="right_foot" pos="0 0 -0.012">
                                    <inertial 
                                        pos="0.03793372	-0.00000219	-0.0443663"
                                        mass="1.28288609"
                                        fullinertia="0.00131328 0.00385286 0.00406301 0.00001057 0.00036242 -0.0000069"
                                    />
                                    <joint name="right_ankle_x" class="alexander/ankle/x"/>
                                    <geom mesh="right_foot" material="gray" class="alexander/visual"/>
                                    <geom name="right_foot_collision" class="alexander/collision/foot"/>
                                    <site name="imu_right_foot" class="alexander/imu/foot"/>
                                    <site name="right_foot_site"/>
                                </body>
                            </body>
                        </body>
                    </body>
                </body>
            </body>
            <body name="torso" pos="0.0 0 0.018">
                <inertial 
                    pos="-0.034 0.0 0.297"
                    mass="7.0081"
                    fullinertia="0.077 0.068 0.033 9.64E-06 0.008 7.24E-06"
                />
                <joint name="spine_z" class="alexander/spine"/>
                <geom mesh="torso" pos="0.0 0.0 0.105063" material="gray" class="alexander/visual"/>
                <site name="imu_torso" class="alexander/imu/torso"/>
                <body name="left_shoulder_y" pos="-0.015 0.115474 0.352984" euler="0.698132 0.0 0.0">
                    <inertial 
                        pos="-0.00264 0.12135 -0.006824"
                        mass="2.99"
                        fullinertia="0.0111046 0.0051699 0.01176 0.0002882 0.000054 0.0009318"
                    />
                    <joint name="left_shoulder_y" class="alexander/shoulder/y"/>
                    <geom mesh="left_shoulder_y" material="gray" class="alexander/visual"/>
                    <site name="imu_left_shoulder_y" class="alexander/imu/shoulder_y/left"/>
                    <body name="left_shoulder_x" pos="0.0 0.15676000 -0.01300000" euler="-0.698132 0.0 0.0">
                        <inertial 
                            pos="0.01251711 0.0188309 -0.03849849"
                            mass="0.972"
                            fullinertia="0.0029485 0.0023587 0.0014366 0.0001386 -0.0003345 0.0005255"
                        />
                        <joint name="left_shoulder_x" class="alexander/shoulder/x/left"/>
                        <geom mesh="left_shoulder_x" material="gray" class="alexander/visual"/>
                        <body name="left_shoulder_z" pos="0.0 0.035 0.0" euler="0.0 0.0 0.0">
                            <inertial 
                                pos="0.00510403 0.00314332 -0.21695413"
                                mass="2.91"
                                fullinertia="0.0267829 0.0265514 0.003052 -0.000011 0.0015998 0.0004426"
                            />
                            <joint name="left_shoulder_z" class="alexander/shoulder/z/left"/>
                            <geom mesh="left_shoulder_z" pos="0.0 0.0 0.0867" material="gray" class="alexander/visual"/>
                            <site name="imu_left_shoulder_z" class="alexander/imu/shoulder_z/left"/>
                            <body name="left_elbow_y" pos="0.015 0.0 -0.3127" euler="0.0 0.0 0.0">
                                <inertial 
                                    pos="-0.01180322 -0.0035763 -0.04946747"
                                    mass="0.45"
                                    fullinertia="0.0007362 0.0006567 0.0004897 -0.0000088 -0.0000292 0.0001499"
                                />
                                <joint name="left_elbow_y" class="alexander/elbow"/>
                                <geom mesh="left_elbow_y" material="gray" class="alexander/visual"/>
                                <body name="left_wrist_z" pos="-0.015 0.0 0.0" euler="0.0 0.0 0.0">
                                    <inertial 
                                        pos="-0.00263832 -0.00050534 -0.13018376"
                                        mass="1.547"
                                        fullinertia="0.0037869 0.004071 0.0015203 0.0000163 -0.0000252 -0.0000924"
                                    />
                                    <joint name="left_wrist_z" class="alexander/wrist/z"/>
                                    <geom mesh="left_wrist_z" material="gray" class="alexander/visual"/>
                                    <site name="imu_left_wrist_z" class="alexander/imu/wrist_z/left"/>
                                    <body name="left_wrist_x" pos="0.0 -0.013 -0.25" euler="0.0 0.0 0.0">
                                        <inertial 
                                            pos="0.00004053 0.01038395 0.00035532"
                                            mass="0.909"
                                            fullinertia="0.000477 0.0004902 0.000514 -0.0000079 -0.0000097 -0.0000008"
                                        />
                                        <joint name="left_wrist_x" class="alexander/wrist/x/left"/>
                                        <geom mesh="left_wrist_x" material="gray" class="alexander/visual"/>
                                        <body name="left_gripper" pos="0.0 0.013 -0.031" euler="0.0 0.0 0.0">
                                            <inertial 
                                                pos="-0.000217 -0.000349 0.009761"
                                                mass="0.251"
                                                fullinertia="0.0000722 0.0000747 0.0000324 -0.0000016 -0.0000037 0.0000004"
                                            />
                                            <geom mesh="left_gripper" quat="0.707 0.0 0.707 0.0" material="gray" class="alexander/visual"/>
                                        </body>
                                    </body>
                                </body>
                            </body>
                        </body>
                    </body>
                </body>
                <body name="neck_z" pos="-0.015 0 0.450403" euler="0.0 0.0 0.0">
                    <inertial 
                        pos="0.007143 0.006943 0.109823"
                        mass="1.141"
                        fullinertia="0.007475898 0.007407578 0.00109269 -0.000075723 -0.000745362 -0.000436948"
                    />
                    <joint name="neck_z" class="alexander/neck/z"/>
                    <geom type="cylinder" size="0.05 0.05" material="gray" class="alexander/visual"/>
                    <body name="head" pos="0.025 0.01 0.189597" euler="0.0 0.0 0.0">
                        <inertial 
                            pos="0.03237 -0.013568 0.007163"
                            mass="1.677"
                            fullinertia="0.006026191 0.008182071 0.00644909 -0.000197484 0.001813659 -0.000042529"
                        />
                        <joint name="neck_y" class="alexander/neck/y"/>
                        <geom mesh="head" material="gray" class="alexander/visual"/>
                        <site name="imu_head" class="alexander/imu/head"/>
                    </body>
                </body>
                <body name="right_shoulder_y" pos="-0.015 -0.115474 0.352984" euler="-0.698132 0.0 0.0">
                    <inertial 
                        pos="-0.00264 -0.12135 -0.006824"
                        mass="2.99"
                        fullinertia="0.0110394 0.0051097 0.0116925 -0.0003041 -0.0000594 -0.0009183"
                    />
                    <joint name="right_shoulder_y" class="alexander/shoulder/y"/>
                    <geom mesh="right_shoulder_y" material="gray" class="alexander/visual"/>
                    <site name="imu_right_shoulder_y" class="alexander/imu/shoulder_y/right"/>
                    <body name="right_shoulder_x" pos="0.0 -0.15676000 -0.01300000" euler="0.698132 0.0 0.0">
                        <inertial 
                            pos="0.012489 -0.01882 -0.0385"
                            mass="0.972"
                            fullinertia="0.002949 0.0023603 0.0014377 -0.000135 -0.0003358 -0.0005249"
                        />
                        <joint name="right_shoulder_x" class="alexander/shoulder/x/right"/>
                        <geom mesh="right_shoulder_x" material="gray" class="alexander/visual"/>
                        <body name="right_shoulder_z" pos="0.0 -0.035 0.0" euler="0.0 0.0 0.0">
                            <inertial 
                                pos="0.00524 -0.00274 -0.21745"
                                mass="2.91"
                                fullinertia="0.0248699 0.0245973 0.0029883 0.0000211 0.0000211 -0.0004444"
                            />
                            <joint name="right_shoulder_z" class="alexander/shoulder/z/right"/>
                            <geom mesh="right_shoulder_z" pos="0.0 0.0 0.0867" material="gray" class="alexander/visual"/>
                            <site name="imu_right_shoulder_z" class="alexander/imu/shoulder_z/right"/>
                            <body name="right_elbow_y" pos="0.015 0.0 -0.3127" euler="0.0 0.0 0.0">
                                <inertial 
                                    pos="-0.0127 0.006913 -0.048421"
                                    mass="0.45"
                                    fullinertia="0.0006446 0.000625 0.0003922 -0.0000073 -0.0000345 -0.0001257"
                                />
                                <joint name="right_elbow_y" class="alexander/elbow"/>
                                <geom mesh="right_elbow_y" material="gray" class="alexander/visual"/>
                                <body name="right_wrist_z" pos="-0.015 0.0 0.0" euler="0.0 0.0 0.0">
                                    <inertial 
                                        pos="-0.002616 0.000462 -0.13019"
                                        mass="1.547"
                                        fullinertia="0.0037805 0.0040639 0.0015151 -0.0000177 -0.000025 0.00009"
                                    />
                                    <joint name="right_wrist_z" class="alexander/wrist/z"/>
                                    <geom mesh="right_wrist_z" material="gray" class="alexander/visual"/>
                                    <site name="imu_right_wrist_z" class="alexander/imu/wrist_z/right"/>
                                    <body name="right_wrist_x" pos="0.0 0.013 -0.25" euler="0.0 0.0 0.0">
                                        <inertial 
                                            pos="-0.0000481 -0.012143 0.000196"
                                            mass="0.909"
                                            fullinertia="0.0005535 0.0005559 0.0005893 0.0000081 -0.0000231 0.0000012"
                                        />
                                        <joint name="right_wrist_x" class="alexander/wrist/x/right"/>
                                        <geom mesh="right_wrist_x" material="gray" class="alexander/visual"/>
                                        <body name="right_gripper" pos="0.0 -0.013 -0.031" euler="0.0 0.0 0.0">
                                            <inertial 
                                                pos="-0.000217 -0.000349 0.009761"
                                                mass="0.251"
                                                fullinertia="0.0000722 0.0000747 0.0000324 -0.0000016 -0.0000037 0.0000004"
                                            />
                                            <geom mesh="right_gripper" quat="0.707 0.0 0.707 0.0" material="gray" class="alexander/visual"/>
                                        </body>
                                    </body>
                                </body>
                            </body>
                        </body>
                    </body>
                </body>
            </body>
        </body>
    </worldbody>

    <actuator>
        <position class="alexander/hip/x" name="left_hip_x" joint="left_hip_x"/>
        <position class="alexander/hip/z" name="left_hip_z" joint="left_hip_z"/>
        <position class="alexander/hip/y" name="left_hip_y" joint="left_hip_y"/>
        <position class="alexander/knee" name="left_knee" joint="left_knee_y"/>
        <position class="alexander/ankle/y" name="left_ankle_y" joint="left_ankle_y"/>
        <position class="alexander/ankle/x" name="left_ankle_x" joint="left_ankle_x"/>
        <position class="alexander/hip/x" name="right_hip_x" joint="right_hip_x"/>
        <position class="alexander/hip/z" name="right_hip_z" joint="right_hip_z"/>
        <position class="alexander/hip/y" name="right_hip_y" joint="right_hip_y"/>
        <position class="alexander/knee" name="right_knee" joint="right_knee_y"/>
        <position class="alexander/ankle/y" name="right_ankle_y" joint="right_ankle_y"/>
        <position class="alexander/ankle/x" name="right_ankle_x" joint="right_ankle_x"/>
        <position class="alexander/spine" name="spine_z" joint="spine_z"/>
        <position class="alexander/shoulder/y" name="left_shoulder_y" joint="left_shoulder_y"/>
        <position class="alexander/shoulder/x" name="left_shoulder_x" joint="left_shoulder_x"/>
        <position class="alexander/shoulder/z" name="left_shoulder_z" joint="left_shoulder_z"/>
        <position class="alexander/elbow" name="left_elbow" joint="left_elbow_y"/>
        <position class="alexander/wrist" name="left_wrist_z" joint="left_wrist_z"/>
        <position class="alexander/wrist" name="left_wrist_x" joint="left_wrist_x"/>
        <position class="alexander/neck" name="neck_z" joint="neck_z"/>
        <position class="alexander/neck" name="neck_y" joint="neck_y"/>
        <position class="alexander/shoulder/y" name="right_shoulder_y" joint="right_shoulder_y"/>
        <position class="alexander/shoulder/x" name="right_shoulder_x" joint="right_shoulder_x"/>
        <position class="alexander/shoulder/z" name="right_shoulder_z" joint="right_shoulder_z"/>
        <position class="alexander/elbow" name="right_elbow" joint="right_elbow_y"/>
        <position class="alexander/wrist" name="right_wrist_z" joint="right_wrist_z"/>
        <position class="alexander/wrist" name="right_wrist_x" joint="right_wrist_x"/>
    </actuator>

    <sensor>
        <!-- Pelvis IMU: -->
         <gyro name="imu_pelvis_gyro" site="imu_pelvis"/>
         <accelerometer name="imu_pelvis_accelerometer" site="imu_pelvis"/>

        <!-- Left Hip IMU: -->
         <gyro name="imu_left_hip_gyro" site="imu_left_hip"/>
         <accelerometer name="imu_left_hip_accelerometer" site="imu_left_hip"/>

         <!-- Left Thight IMU: -->
        <gyro name="imu_left_thigh_gyro" site="imu_left_thigh"/>
        <accelerometer name="imu_left_thigh_accelerometer" site="imu_left_thigh"/>

        <!-- Left Shin IMU: -->
        <gyro name="imu_left_shin_gyro" site="imu_left_shin"/>
        <accelerometer name="imu_left_shin_accelerometer" site="imu_left_shin"/>

        <!-- Left Foot IMU: -->
        <gyro name="imu_left_foot_gyro" site="imu_left_foot"/>
        <accelerometer name="imu_left_foot_accelerometer" site="imu_left_foot"/>

        <!-- Right Hip IMU: -->
         <gyro name="imu_right_hip_gyro" site="imu_right_hip"/>
         <accelerometer name="imu_right_hip_accelerometer" site="imu_right_hip"/>

         <!-- Right Thight IMU: -->
        <gyro name="imu_right_thigh_gyro" site="imu_right_thigh"/>
        <accelerometer name="imu_right_thigh_accelerometer" site="imu_right_thigh"/>

        <!-- Right Shin IMU: -->
        <gyro name="imu_right_shin_gyro" site="imu_right_shin"/>
        <accelerometer name="imu_right_shin_accelerometer" site="imu_right_shin"/>

        <!-- Right Foot IMU: -->
        <gyro name="imu_right_foot_gyro" site="imu_right_foot"/>
        <accelerometer name="imu_right_foot_accelerometer" site="imu_right_foot"/>

        <!-- Torso IMU: -->
        <gyro name="imu_torso_gyro" site="imu_torso"/>
        <accelerometer name="imu_torso_accelerometer" site="imu_torso"/>

        <!-- Head IMU: -->
        <gyro name="imu_head_gyro" site="imu_head"/>
        <accelerometer name="imu_head_accelerometer" site="imu_head"/>

        <!-- Left Shoulder Pitch IMU: -->
        <gyro name="imu_left_shoulder_y_gyro" site="imu_left_shoulder_y"/>
        <accelerometer name="imu_left_shoulder_y_accelerometer" site="imu_left_shoulder_y"/>

        <!-- Left Shoulder Yaw IMU: -->
        <gyro name="imu_left_shoulder_z_gyro" site="imu_left_shoulder_z"/>
        <accelerometer name="imu_left_shoulder_z_accelerometer" site="imu_left_shoulder_z"/>

        <!-- Left Wrist Yaw IMU: -->
        <gyro name="imu_left_wrist_z_gyro" site="imu_left_wrist_z"/>
        <accelerometer name="imu_left_wrist_z_accelerometer" site="imu_left_wrist_z"/>
        
        <!-- Right Shoulder Pitch IMU: -->
        <gyro name="imu_right_shoulder_y_gyro" site="imu_right_shoulder_y"/>
        <accelerometer name="imu_right_shoulder_y_accelerometer" site="imu_right_shoulder_y"/>

        <!-- Right Shoulder Yaw IMU: -->
        <gyro name="imu_right_shoulder_z_gyro" site="imu_right_shoulder_z"/>
        <accelerometer name="imu_right_shoulder_z_accelerometer" site="imu_right_shoulder_z"/>

        <!-- Right Wrist Yaw IMU: -->
        <gyro name="imu_right_wrist_z_gyro" site="imu_right_wrist_z"/>
        <accelerometer name="imu_right_wrist_z_accelerometer" site="imu_right_wrist_z"/>

        <!-- Additional Sensors for training: -->
        <!-- Pelvis IMU: -->
        <framequat name="imu_pelvis_orientation" objtype="site" objname="imu_pelvis"/>
        <velocimeter name="imu_pelvis_linear_velocity" site="imu_pelvis"/>
        <framepos name="imu_pelvis_position" objtype="site" objname="imu_pelvis"/>

        <!-- Globals: -->
        <framezaxis name="upvector" objtype="site" objname="imu_pelvis"/>
        <framexaxis name="forwardvector" objtype="site" objname="imu_pelvis"/>
        <framelinvel name="global_linear_velocity" objtype="site" objname="imu_pelvis"/>
        <frameangvel name="global_angular_velocity" objtype="site" objname="imu_pelvis"/>
        <framelinvel name="left_foot_global_linear_velocity" objtype="site" objname="left_foot_site"/>
        <framelinvel name="right_foot_global_linear_velocity" objtype="site" objname="right_foot_site"/>
    </sensor>

</mujoco>