<?xml version = "1.0" ?>
<robot name="Alexander">

    <!-- Right Arm -->
    <joint name="RIGHT_SHOULDER_Y" type="revolute">
        <origin xyz="-0.015 -0.115474 0.352984" rpy="-0.698132 0.0 0.0"/>
        <axis xyz="0.0 1.0 0.0"/>
        <parent link="TORSO_LINK"/>
        <child link="RIGHT_SHOULDER_Y_LINK"/>
        <limit effort="1000" lower="-3.141592" upper="1.22173" velocity="100"/>
        <dynamics damping="0.05" friction="0.0"/>
    </joint>

    <link name="RIGHT_SHOULDER_Y_LINK">
        <inertial>
            <mass value="2.99"/>
            <origin rpy="0 0 0" xyz="-0.00264 -0.12135 -0.006824"/>
            <inertia ixx="0.0110394" ixy="-0.0003041" ixz="-0.0000594" iyy="0.0051097" iyz="-0.0009183" izz="0.0116925"/>
        </inertial>
        <visual>
            <geometry>
                <mesh filename="package://alexander_V1_description/meshes/cycloidal_arm/RightShoulderPitchLink.obj"/>
            </geometry>
            <origin rpy="0.0 0.0 0.0" xyz="0.0 0.0 0.0"/>
        </visual>
    </link>

    <!-- RIGHT SHOULDER PITCH IMU INFORMATION -->
    <joint name="RIGHT_SHOULDER_Y_IMU_JOINT" type="fixed">
        <origin rpy="1.570796 -1.570796 0" xyz="0.0175 -0.0704 -0.00778"/>
        <axis xyz="0 0 1"/>
        <parent link="RIGHT_SHOULDER_Y_LINK"/>
        <child link="RIGHT_SHOULDER_Y_IMU_LINK"/>
    </joint>
    <link name="RIGHT_SHOULDER_Y_IMU_LINK">
        <inertial>
            <mass value="0"/>
            <origin rpy="0 0 0" xyz="0 0 0"/>
            <inertia ixx="0.0" ixy="0.0" ixz="0.0" iyy="0.0" iyz="0.0" izz="0.0"/>
        </inertial>
    </link>
    <gazebo reference="RIGHT_SHOULDER_Y_IMU_LINK">
        <sensor name="right_shoulder_y_imu" type="imu">
            <always_on>true</always_on>
            <imu>
                <noise>
                    <type>gaussian</type>
                    <rate>
                        <mean>0</mean>
                        <stddev>0.0002</stddev>
                        <bias_mean>7.5e-06</bias_mean>
                        <bias_stddev>8e-07</bias_stddev>
                    </rate>
                    <accel>
                        <mean>0</mean>
                        <stddev>0.017</stddev>
                        <bias_mean>0.1</bias_mean>
                        <bias_stddev>0.001</bias_stddev>
                    </accel>
                </noise>
            </imu>
        </sensor>
    </gazebo>

    <joint name="RIGHT_SHOULDER_X" type="revolute">
        <origin rpy="0.698132 0.0 0.0" xyz="0.0 -0.15676000 -0.01300000"/>
        <axis xyz="1 0 0"/>
        <parent link="RIGHT_SHOULDER_Y_LINK"/>
        <child link="RIGHT_SHOULDER_X_LINK"/>
        <limit effort="1000" lower="-2.79253" upper="0.349066" velocity="100"/>
        <dynamics damping="0.05" friction="0.0"/>
    </joint>

    <link name="RIGHT_SHOULDER_X_LINK">
        <inertial>
            <mass value="1.17068"/>
            <origin rpy="0 0 0" xyz="0.01053 -0.02124 -0.1052690"/>
            <inertia ixx="0.00787035" ixy="-1.667e-4" ixz="-0.00075945" iyy="0.00727481" iyz="-0.000988837" izz="0.00182144"/>
        </inertial>
        <visual>
            <geometry>
                <mesh filename="package://alexander_V1_description/meshes/cycloidal_arm/RightShoulderRollLink_longBicep.obj"/>
            </geometry>
            <origin rpy="0.0 0.0 0.0" xyz="0.0 0.0 0.0"/>
        </visual>
    </link>

    <joint name="RIGHT_SHOULDER_Z" type="revolute">
        <origin rpy="0.0 0.0 0.0" xyz="0.0 -0.035 -0.08"/>
        <axis xyz="0.0 0.0 1.0"/>
        <parent link="RIGHT_SHOULDER_X_LINK"/>
        <child link="RIGHT_SHOULDER_Z_LINK"/>
        <limit effort="1000" lower="-1.22173" upper="1.91986" velocity="100"/>
        <dynamics damping="0.05" friction="0.0"/>
    </joint>

    <link name="RIGHT_SHOULDER_Z_LINK">
        <inertial>
            <mass value="2.91"/>
            <origin rpy="0 0 0" xyz="0.00524 -0.00274 -0.21745"/>
            <inertia ixx="0.0267829" ixy="0.000011" ixz="0.0015998" iyy="0.0265514" iyz="-0.0004426" izz="0.003052"/>
        </inertial>
        <visual>
            <geometry>
                <mesh filename="package://alexander_V1_description/meshes/cycloidal_arm/RightShoulderYawLink.obj"/>
            </geometry>
            <origin rpy="0.0 0.0 0.0" xyz="0.0 0.0 0.0867"/>
        </visual>
    </link>

    <!-- RIGHT SHOULDER YAW IMU -->
    <joint name="RIGHT_SHOULDER_Z_IMU_JOINT" type="fixed">
        <origin rpy="1.570796 0 0.314159" xyz="0.002 0.016 -0.318"/>
        <axis xyz="0 0 1"/>
        <parent link="RIGHT_SHOULDER_Z_LINK"/>
        <child link="RIGHT_SHOULDER_Z_IMU_LINK"/>
    </joint>

    <link name="RIGHT_SHOULDER_Z_IMU_LINK">
        <inertial>
            <mass value="0"/>
            <origin rpy="0 0 0" xyz="0 0 0"/>
            <inertia ixx="0.0" ixy="0.0" ixz="0.0" iyy="0.0" iyz="0.0" izz="0.0"/>
        </inertial>
    </link>

    <gazebo reference="RIGHT_SHOULDER_Z_IMU_LINK">
        <sensor name="right_shoulder_z_imu" type="imu">
            <always_on>true</always_on>
            <imu>
                <noise>
                    <type>gaussian</type>
                    <rate>
                        <mean>0</mean>
                        <stddev>0.0002</stddev>
                        <bias_mean>7.5e-06</bias_mean>
                        <bias_stddev>8e-07</bias_stddev>
                    </rate>
                    <accel>
                        <mean>0</mean>
                        <stddev>0.017</stddev>
                        <bias_mean>0.1</bias_mean>
                        <bias_stddev>0.001</bias_stddev>
                    </accel>
                </noise>
            </imu>
        </sensor>
    </gazebo>

</robot>