<?xml version = "1.0" ?>
<robot name="Alexander">


    <joint name="RIGHT_ELBOW_Y" type="revolute">
        <origin rpy="0.0 0.0 0.0" xyz="0.015 0.0 -0.3127"/>
        <axis xyz="0.0 1.0 0.0"/>
        <parent link="RIGHT_SHOULDER_Z_LINK"/>
        <child link="RIGHT_ELBOW_Y_LINK"/>
        <limit effort="1000" lower="-2.35619" upper="0.174532925" velocity="100"/>
        <dynamics damping="0.05" friction="0.0"/>
    </joint>

    <link name="RIGHT_ELBOW_Y_LINK">
        <inertial>
            <!-- Normal forearm knub -->
            <mass value="0.616"/>
            <origin rpy="0 0 0" xyz="-0.01090935 0.01147189 -0.10388715"/>
            <inertia ixx="0.00760733" ixy="-2.242e-5" ixz="-2.583e-4" iyy="0.00767556" iyz="-0.00061995" izz="4.554e-4"/>

            <!-- 12lbs dumbbell -->
            <!--<mass value="5.9"/>-->
            <!--<origin rpy="0 0 0" xyz="0.05 0.0 -0.225"/>-->
            <!--<inertia ixx="0.05" ixy="2.242e-5" ixz="-2.583e-4" iyy="0.015" iyz="0.00061995" izz="0.05" />-->
        </inertial>
        <visual>
            <geometry>
                <mesh filename="package://alexander_V1_description/meshes/cycloidal_arm/RIGHT_ELBOW_PITCH_LINK_413mm_LENGTH.obj"/>
            </geometry>
            <origin rpy="0.0 0.0 0.0" xyz="0.0 0.0 0.0"/>
        </visual>
    </link>

</robot>